[2024-01-27T07:51:41.865+0000] {processor.py:154} INFO - Started process (PID=1245) to work on /opt/airflow/dags/user_processing.py
[2024-01-27T07:51:41.866+0000] {processor.py:756} INFO - Processing file /opt/airflow/dags/user_processing.py for tasks to queue
[2024-01-27T07:51:41.867+0000] {logging_mixin.py:120} INFO - [2024-01-27T07:51:41.867+0000] {dagbag.py:537} INFO - Filling up the DagBag from /opt/airflow/dags/user_processing.py
[2024-01-27T07:51:42.646+0000] {logging_mixin.py:120} INFO - [2024-01-27T07:51:42.641+0000] {dagbag.py:342} ERROR - Failed to import: /opt/airflow/dags/user_processing.py
Traceback (most recent call last):
  File "/home/airflow/.local/lib/python3.7/site-packages/airflow/models/dagbag.py", line 338, in parse
    loader.exec_module(new_module)
  File "<frozen importlib._bootstrap_external>", line 728, in exec_module
  File "<frozen importlib._bootstrap>", line 219, in _call_with_frames_removed
  File "/opt/airflow/dags/user_processing.py", line 62, in <module>
    python_callbale=_process_user
  File "/home/airflow/.local/lib/python3.7/site-packages/airflow/models/baseoperator.py", line 391, in apply_defaults
    raise AirflowException(f"missing keyword argument {missing_args.pop()!r}")
airflow.exceptions.AirflowException: missing keyword argument 'python_callable'
[2024-01-27T07:51:42.647+0000] {processor.py:768} WARNING - No viable dags retrieved from /opt/airflow/dags/user_processing.py
[2024-01-27T07:51:42.663+0000] {processor.py:176} INFO - Processing /opt/airflow/dags/user_processing.py took 0.802 seconds
[2024-01-27T07:52:13.251+0000] {processor.py:154} INFO - Started process (PID=1313) to work on /opt/airflow/dags/user_processing.py
[2024-01-27T07:52:13.253+0000] {processor.py:756} INFO - Processing file /opt/airflow/dags/user_processing.py for tasks to queue
[2024-01-27T07:52:13.255+0000] {logging_mixin.py:120} INFO - [2024-01-27T07:52:13.255+0000] {dagbag.py:537} INFO - Filling up the DagBag from /opt/airflow/dags/user_processing.py
[2024-01-27T07:52:13.618+0000] {logging_mixin.py:120} INFO - [2024-01-27T07:52:13.615+0000] {dagbag.py:342} ERROR - Failed to import: /opt/airflow/dags/user_processing.py
Traceback (most recent call last):
  File "/home/airflow/.local/lib/python3.7/site-packages/airflow/models/dagbag.py", line 338, in parse
    loader.exec_module(new_module)
  File "<frozen importlib._bootstrap_external>", line 728, in exec_module
  File "<frozen importlib._bootstrap>", line 219, in _call_with_frames_removed
  File "/opt/airflow/dags/user_processing.py", line 62, in <module>
    python_callbale=_process_user
  File "/home/airflow/.local/lib/python3.7/site-packages/airflow/models/baseoperator.py", line 391, in apply_defaults
    raise AirflowException(f"missing keyword argument {missing_args.pop()!r}")
airflow.exceptions.AirflowException: missing keyword argument 'python_callable'
[2024-01-27T07:52:13.620+0000] {processor.py:768} WARNING - No viable dags retrieved from /opt/airflow/dags/user_processing.py
[2024-01-27T07:52:13.638+0000] {processor.py:176} INFO - Processing /opt/airflow/dags/user_processing.py took 0.392 seconds
[2024-01-27T07:52:44.658+0000] {processor.py:154} INFO - Started process (PID=1377) to work on /opt/airflow/dags/user_processing.py
[2024-01-27T07:52:44.661+0000] {processor.py:756} INFO - Processing file /opt/airflow/dags/user_processing.py for tasks to queue
[2024-01-27T07:52:44.663+0000] {logging_mixin.py:120} INFO - [2024-01-27T07:52:44.662+0000] {dagbag.py:537} INFO - Filling up the DagBag from /opt/airflow/dags/user_processing.py
[2024-01-27T07:52:45.029+0000] {logging_mixin.py:120} INFO - [2024-01-27T07:52:45.025+0000] {dagbag.py:342} ERROR - Failed to import: /opt/airflow/dags/user_processing.py
Traceback (most recent call last):
  File "/home/airflow/.local/lib/python3.7/site-packages/airflow/models/dagbag.py", line 338, in parse
    loader.exec_module(new_module)
  File "<frozen importlib._bootstrap_external>", line 728, in exec_module
  File "<frozen importlib._bootstrap>", line 219, in _call_with_frames_removed
  File "/opt/airflow/dags/user_processing.py", line 62, in <module>
    python_callbale=_process_user
  File "/home/airflow/.local/lib/python3.7/site-packages/airflow/models/baseoperator.py", line 391, in apply_defaults
    raise AirflowException(f"missing keyword argument {missing_args.pop()!r}")
airflow.exceptions.AirflowException: missing keyword argument 'python_callable'
[2024-01-27T07:52:45.032+0000] {processor.py:768} WARNING - No viable dags retrieved from /opt/airflow/dags/user_processing.py
[2024-01-27T07:52:45.047+0000] {processor.py:176} INFO - Processing /opt/airflow/dags/user_processing.py took 0.393 seconds
[2024-01-27T07:53:15.987+0000] {processor.py:154} INFO - Started process (PID=1442) to work on /opt/airflow/dags/user_processing.py
[2024-01-27T07:53:15.989+0000] {processor.py:756} INFO - Processing file /opt/airflow/dags/user_processing.py for tasks to queue
[2024-01-27T07:53:15.991+0000] {logging_mixin.py:120} INFO - [2024-01-27T07:53:15.991+0000] {dagbag.py:537} INFO - Filling up the DagBag from /opt/airflow/dags/user_processing.py
[2024-01-27T07:53:16.394+0000] {logging_mixin.py:120} INFO - [2024-01-27T07:53:16.391+0000] {dagbag.py:342} ERROR - Failed to import: /opt/airflow/dags/user_processing.py
Traceback (most recent call last):
  File "/home/airflow/.local/lib/python3.7/site-packages/airflow/models/dagbag.py", line 338, in parse
    loader.exec_module(new_module)
  File "<frozen importlib._bootstrap_external>", line 728, in exec_module
  File "<frozen importlib._bootstrap>", line 219, in _call_with_frames_removed
  File "/opt/airflow/dags/user_processing.py", line 62, in <module>
    python_callbale=_process_user
  File "/home/airflow/.local/lib/python3.7/site-packages/airflow/models/baseoperator.py", line 391, in apply_defaults
    raise AirflowException(f"missing keyword argument {missing_args.pop()!r}")
airflow.exceptions.AirflowException: missing keyword argument 'python_callable'
[2024-01-27T07:53:16.396+0000] {processor.py:768} WARNING - No viable dags retrieved from /opt/airflow/dags/user_processing.py
[2024-01-27T07:53:16.414+0000] {processor.py:176} INFO - Processing /opt/airflow/dags/user_processing.py took 0.429 seconds
[2024-01-27T07:53:46.476+0000] {processor.py:154} INFO - Started process (PID=1498) to work on /opt/airflow/dags/user_processing.py
[2024-01-27T07:53:46.480+0000] {processor.py:756} INFO - Processing file /opt/airflow/dags/user_processing.py for tasks to queue
[2024-01-27T07:53:46.482+0000] {logging_mixin.py:120} INFO - [2024-01-27T07:53:46.481+0000] {dagbag.py:537} INFO - Filling up the DagBag from /opt/airflow/dags/user_processing.py
[2024-01-27T07:53:46.934+0000] {logging_mixin.py:120} INFO - [2024-01-27T07:53:46.930+0000] {dagbag.py:342} ERROR - Failed to import: /opt/airflow/dags/user_processing.py
Traceback (most recent call last):
  File "/home/airflow/.local/lib/python3.7/site-packages/airflow/models/dagbag.py", line 338, in parse
    loader.exec_module(new_module)
  File "<frozen importlib._bootstrap_external>", line 728, in exec_module
  File "<frozen importlib._bootstrap>", line 219, in _call_with_frames_removed
  File "/opt/airflow/dags/user_processing.py", line 62, in <module>
    python_callbale=_process_user
  File "/home/airflow/.local/lib/python3.7/site-packages/airflow/models/baseoperator.py", line 391, in apply_defaults
    raise AirflowException(f"missing keyword argument {missing_args.pop()!r}")
airflow.exceptions.AirflowException: missing keyword argument 'python_callable'
[2024-01-27T07:53:46.936+0000] {processor.py:768} WARNING - No viable dags retrieved from /opt/airflow/dags/user_processing.py
[2024-01-27T07:53:46.955+0000] {processor.py:176} INFO - Processing /opt/airflow/dags/user_processing.py took 0.485 seconds
[2024-01-27T07:54:17.125+0000] {processor.py:154} INFO - Started process (PID=1563) to work on /opt/airflow/dags/user_processing.py
[2024-01-27T07:54:17.128+0000] {processor.py:756} INFO - Processing file /opt/airflow/dags/user_processing.py for tasks to queue
[2024-01-27T07:54:17.130+0000] {logging_mixin.py:120} INFO - [2024-01-27T07:54:17.130+0000] {dagbag.py:537} INFO - Filling up the DagBag from /opt/airflow/dags/user_processing.py
[2024-01-27T07:54:17.562+0000] {logging_mixin.py:120} INFO - [2024-01-27T07:54:17.559+0000] {dagbag.py:342} ERROR - Failed to import: /opt/airflow/dags/user_processing.py
Traceback (most recent call last):
  File "/home/airflow/.local/lib/python3.7/site-packages/airflow/models/dagbag.py", line 338, in parse
    loader.exec_module(new_module)
  File "<frozen importlib._bootstrap_external>", line 728, in exec_module
  File "<frozen importlib._bootstrap>", line 219, in _call_with_frames_removed
  File "/opt/airflow/dags/user_processing.py", line 62, in <module>
    python_callbale=_process_user
  File "/home/airflow/.local/lib/python3.7/site-packages/airflow/models/baseoperator.py", line 391, in apply_defaults
    raise AirflowException(f"missing keyword argument {missing_args.pop()!r}")
airflow.exceptions.AirflowException: missing keyword argument 'python_callable'
[2024-01-27T07:54:17.564+0000] {processor.py:768} WARNING - No viable dags retrieved from /opt/airflow/dags/user_processing.py
[2024-01-27T07:54:17.582+0000] {processor.py:176} INFO - Processing /opt/airflow/dags/user_processing.py took 0.461 seconds
[2024-01-27T07:54:47.706+0000] {processor.py:154} INFO - Started process (PID=1626) to work on /opt/airflow/dags/user_processing.py
[2024-01-27T07:54:47.710+0000] {processor.py:756} INFO - Processing file /opt/airflow/dags/user_processing.py for tasks to queue
[2024-01-27T07:54:47.712+0000] {logging_mixin.py:120} INFO - [2024-01-27T07:54:47.712+0000] {dagbag.py:537} INFO - Filling up the DagBag from /opt/airflow/dags/user_processing.py
[2024-01-27T07:54:48.079+0000] {logging_mixin.py:120} INFO - [2024-01-27T07:54:48.075+0000] {dagbag.py:342} ERROR - Failed to import: /opt/airflow/dags/user_processing.py
Traceback (most recent call last):
  File "/home/airflow/.local/lib/python3.7/site-packages/airflow/models/dagbag.py", line 338, in parse
    loader.exec_module(new_module)
  File "<frozen importlib._bootstrap_external>", line 728, in exec_module
  File "<frozen importlib._bootstrap>", line 219, in _call_with_frames_removed
  File "/opt/airflow/dags/user_processing.py", line 62, in <module>
    python_callbale=_process_user
  File "/home/airflow/.local/lib/python3.7/site-packages/airflow/models/baseoperator.py", line 391, in apply_defaults
    raise AirflowException(f"missing keyword argument {missing_args.pop()!r}")
airflow.exceptions.AirflowException: missing keyword argument 'python_callable'
[2024-01-27T07:54:48.082+0000] {processor.py:768} WARNING - No viable dags retrieved from /opt/airflow/dags/user_processing.py
[2024-01-27T07:54:48.098+0000] {processor.py:176} INFO - Processing /opt/airflow/dags/user_processing.py took 0.395 seconds
[2024-01-27T07:55:18.193+0000] {processor.py:154} INFO - Started process (PID=1689) to work on /opt/airflow/dags/user_processing.py
[2024-01-27T07:55:18.198+0000] {processor.py:756} INFO - Processing file /opt/airflow/dags/user_processing.py for tasks to queue
[2024-01-27T07:55:18.201+0000] {logging_mixin.py:120} INFO - [2024-01-27T07:55:18.201+0000] {dagbag.py:537} INFO - Filling up the DagBag from /opt/airflow/dags/user_processing.py
[2024-01-27T07:55:18.603+0000] {logging_mixin.py:120} INFO - [2024-01-27T07:55:18.600+0000] {dagbag.py:342} ERROR - Failed to import: /opt/airflow/dags/user_processing.py
Traceback (most recent call last):
  File "/home/airflow/.local/lib/python3.7/site-packages/airflow/models/dagbag.py", line 338, in parse
    loader.exec_module(new_module)
  File "<frozen importlib._bootstrap_external>", line 728, in exec_module
  File "<frozen importlib._bootstrap>", line 219, in _call_with_frames_removed
  File "/opt/airflow/dags/user_processing.py", line 62, in <module>
    python_callbale=_process_user
  File "/home/airflow/.local/lib/python3.7/site-packages/airflow/models/baseoperator.py", line 391, in apply_defaults
    raise AirflowException(f"missing keyword argument {missing_args.pop()!r}")
airflow.exceptions.AirflowException: missing keyword argument 'python_callable'
[2024-01-27T07:55:18.604+0000] {processor.py:768} WARNING - No viable dags retrieved from /opt/airflow/dags/user_processing.py
[2024-01-27T07:55:18.622+0000] {processor.py:176} INFO - Processing /opt/airflow/dags/user_processing.py took 0.434 seconds
[2024-01-27T07:55:48.812+0000] {processor.py:154} INFO - Started process (PID=1753) to work on /opt/airflow/dags/user_processing.py
[2024-01-27T07:55:48.814+0000] {processor.py:756} INFO - Processing file /opt/airflow/dags/user_processing.py for tasks to queue
[2024-01-27T07:55:48.816+0000] {logging_mixin.py:120} INFO - [2024-01-27T07:55:48.815+0000] {dagbag.py:537} INFO - Filling up the DagBag from /opt/airflow/dags/user_processing.py
[2024-01-27T07:55:49.200+0000] {logging_mixin.py:120} INFO - [2024-01-27T07:55:49.197+0000] {dagbag.py:342} ERROR - Failed to import: /opt/airflow/dags/user_processing.py
Traceback (most recent call last):
  File "/home/airflow/.local/lib/python3.7/site-packages/airflow/models/dagbag.py", line 338, in parse
    loader.exec_module(new_module)
  File "<frozen importlib._bootstrap_external>", line 728, in exec_module
  File "<frozen importlib._bootstrap>", line 219, in _call_with_frames_removed
  File "/opt/airflow/dags/user_processing.py", line 62, in <module>
    python_callbale=_process_user
  File "/home/airflow/.local/lib/python3.7/site-packages/airflow/models/baseoperator.py", line 391, in apply_defaults
    raise AirflowException(f"missing keyword argument {missing_args.pop()!r}")
airflow.exceptions.AirflowException: missing keyword argument 'python_callable'
[2024-01-27T07:55:49.202+0000] {processor.py:768} WARNING - No viable dags retrieved from /opt/airflow/dags/user_processing.py
[2024-01-27T07:55:49.217+0000] {processor.py:176} INFO - Processing /opt/airflow/dags/user_processing.py took 0.407 seconds
[2024-01-27T07:56:19.507+0000] {processor.py:154} INFO - Started process (PID=1815) to work on /opt/airflow/dags/user_processing.py
[2024-01-27T07:56:19.510+0000] {processor.py:756} INFO - Processing file /opt/airflow/dags/user_processing.py for tasks to queue
[2024-01-27T07:56:19.513+0000] {logging_mixin.py:120} INFO - [2024-01-27T07:56:19.513+0000] {dagbag.py:537} INFO - Filling up the DagBag from /opt/airflow/dags/user_processing.py
[2024-01-27T07:56:20.102+0000] {logging_mixin.py:120} INFO - [2024-01-27T07:56:20.097+0000] {dagbag.py:342} ERROR - Failed to import: /opt/airflow/dags/user_processing.py
Traceback (most recent call last):
  File "/home/airflow/.local/lib/python3.7/site-packages/airflow/models/dagbag.py", line 338, in parse
    loader.exec_module(new_module)
  File "<frozen importlib._bootstrap_external>", line 728, in exec_module
  File "<frozen importlib._bootstrap>", line 219, in _call_with_frames_removed
  File "/opt/airflow/dags/user_processing.py", line 62, in <module>
    python_callbale=_process_user
  File "/home/airflow/.local/lib/python3.7/site-packages/airflow/models/baseoperator.py", line 391, in apply_defaults
    raise AirflowException(f"missing keyword argument {missing_args.pop()!r}")
airflow.exceptions.AirflowException: missing keyword argument 'python_callable'
[2024-01-27T07:56:20.104+0000] {processor.py:768} WARNING - No viable dags retrieved from /opt/airflow/dags/user_processing.py
[2024-01-27T07:56:20.168+0000] {processor.py:176} INFO - Processing /opt/airflow/dags/user_processing.py took 0.665 seconds
[2024-01-27T07:56:50.218+0000] {processor.py:154} INFO - Started process (PID=1872) to work on /opt/airflow/dags/user_processing.py
[2024-01-27T07:56:50.220+0000] {processor.py:756} INFO - Processing file /opt/airflow/dags/user_processing.py for tasks to queue
[2024-01-27T07:56:50.222+0000] {logging_mixin.py:120} INFO - [2024-01-27T07:56:50.222+0000] {dagbag.py:537} INFO - Filling up the DagBag from /opt/airflow/dags/user_processing.py
[2024-01-27T07:56:50.718+0000] {logging_mixin.py:120} INFO - [2024-01-27T07:56:50.715+0000] {dagbag.py:342} ERROR - Failed to import: /opt/airflow/dags/user_processing.py
Traceback (most recent call last):
  File "/home/airflow/.local/lib/python3.7/site-packages/airflow/models/dagbag.py", line 338, in parse
    loader.exec_module(new_module)
  File "<frozen importlib._bootstrap_external>", line 728, in exec_module
  File "<frozen importlib._bootstrap>", line 219, in _call_with_frames_removed
  File "/opt/airflow/dags/user_processing.py", line 62, in <module>
    python_callbale=_process_user
  File "/home/airflow/.local/lib/python3.7/site-packages/airflow/models/baseoperator.py", line 391, in apply_defaults
    raise AirflowException(f"missing keyword argument {missing_args.pop()!r}")
airflow.exceptions.AirflowException: missing keyword argument 'python_callable'
[2024-01-27T07:56:50.720+0000] {processor.py:768} WARNING - No viable dags retrieved from /opt/airflow/dags/user_processing.py
[2024-01-27T07:56:50.737+0000] {processor.py:176} INFO - Processing /opt/airflow/dags/user_processing.py took 0.523 seconds
[2024-01-27T07:57:21.598+0000] {processor.py:154} INFO - Started process (PID=1937) to work on /opt/airflow/dags/user_processing.py
[2024-01-27T07:57:21.601+0000] {processor.py:756} INFO - Processing file /opt/airflow/dags/user_processing.py for tasks to queue
[2024-01-27T07:57:21.603+0000] {logging_mixin.py:120} INFO - [2024-01-27T07:57:21.603+0000] {dagbag.py:537} INFO - Filling up the DagBag from /opt/airflow/dags/user_processing.py
[2024-01-27T07:57:22.042+0000] {logging_mixin.py:120} INFO - [2024-01-27T07:57:22.038+0000] {dagbag.py:342} ERROR - Failed to import: /opt/airflow/dags/user_processing.py
Traceback (most recent call last):
  File "/home/airflow/.local/lib/python3.7/site-packages/airflow/models/dagbag.py", line 338, in parse
    loader.exec_module(new_module)
  File "<frozen importlib._bootstrap_external>", line 728, in exec_module
  File "<frozen importlib._bootstrap>", line 219, in _call_with_frames_removed
  File "/opt/airflow/dags/user_processing.py", line 62, in <module>
    python_callbale=_process_user
  File "/home/airflow/.local/lib/python3.7/site-packages/airflow/models/baseoperator.py", line 391, in apply_defaults
    raise AirflowException(f"missing keyword argument {missing_args.pop()!r}")
airflow.exceptions.AirflowException: missing keyword argument 'python_callable'
[2024-01-27T07:57:22.044+0000] {processor.py:768} WARNING - No viable dags retrieved from /opt/airflow/dags/user_processing.py
[2024-01-27T07:57:22.061+0000] {processor.py:176} INFO - Processing /opt/airflow/dags/user_processing.py took 0.468 seconds
[2024-01-27T07:57:52.792+0000] {processor.py:154} INFO - Started process (PID=2002) to work on /opt/airflow/dags/user_processing.py
[2024-01-27T07:57:52.794+0000] {processor.py:756} INFO - Processing file /opt/airflow/dags/user_processing.py for tasks to queue
[2024-01-27T07:57:52.796+0000] {logging_mixin.py:120} INFO - [2024-01-27T07:57:52.796+0000] {dagbag.py:537} INFO - Filling up the DagBag from /opt/airflow/dags/user_processing.py
[2024-01-27T07:57:53.224+0000] {logging_mixin.py:120} INFO - [2024-01-27T07:57:53.221+0000] {dagbag.py:342} ERROR - Failed to import: /opt/airflow/dags/user_processing.py
Traceback (most recent call last):
  File "/home/airflow/.local/lib/python3.7/site-packages/airflow/models/dagbag.py", line 338, in parse
    loader.exec_module(new_module)
  File "<frozen importlib._bootstrap_external>", line 728, in exec_module
  File "<frozen importlib._bootstrap>", line 219, in _call_with_frames_removed
  File "/opt/airflow/dags/user_processing.py", line 62, in <module>
    python_callbale=_process_user
  File "/home/airflow/.local/lib/python3.7/site-packages/airflow/models/baseoperator.py", line 391, in apply_defaults
    raise AirflowException(f"missing keyword argument {missing_args.pop()!r}")
airflow.exceptions.AirflowException: missing keyword argument 'python_callable'
[2024-01-27T07:57:53.225+0000] {processor.py:768} WARNING - No viable dags retrieved from /opt/airflow/dags/user_processing.py
[2024-01-27T07:57:53.241+0000] {processor.py:176} INFO - Processing /opt/airflow/dags/user_processing.py took 0.455 seconds
[2024-01-27T07:58:23.503+0000] {processor.py:154} INFO - Started process (PID=2068) to work on /opt/airflow/dags/user_processing.py
[2024-01-27T07:58:23.506+0000] {processor.py:756} INFO - Processing file /opt/airflow/dags/user_processing.py for tasks to queue
[2024-01-27T07:58:23.507+0000] {logging_mixin.py:120} INFO - [2024-01-27T07:58:23.507+0000] {dagbag.py:537} INFO - Filling up the DagBag from /opt/airflow/dags/user_processing.py
[2024-01-27T07:58:23.932+0000] {logging_mixin.py:120} INFO - [2024-01-27T07:58:23.929+0000] {dagbag.py:342} ERROR - Failed to import: /opt/airflow/dags/user_processing.py
Traceback (most recent call last):
  File "/home/airflow/.local/lib/python3.7/site-packages/airflow/models/dagbag.py", line 338, in parse
    loader.exec_module(new_module)
  File "<frozen importlib._bootstrap_external>", line 728, in exec_module
  File "<frozen importlib._bootstrap>", line 219, in _call_with_frames_removed
  File "/opt/airflow/dags/user_processing.py", line 62, in <module>
    python_callbale=_process_user
  File "/home/airflow/.local/lib/python3.7/site-packages/airflow/models/baseoperator.py", line 391, in apply_defaults
    raise AirflowException(f"missing keyword argument {missing_args.pop()!r}")
airflow.exceptions.AirflowException: missing keyword argument 'python_callable'
[2024-01-27T07:58:23.934+0000] {processor.py:768} WARNING - No viable dags retrieved from /opt/airflow/dags/user_processing.py
[2024-01-27T07:58:23.951+0000] {processor.py:176} INFO - Processing /opt/airflow/dags/user_processing.py took 0.452 seconds
[2024-01-27T07:58:54.219+0000] {processor.py:154} INFO - Started process (PID=2132) to work on /opt/airflow/dags/user_processing.py
[2024-01-27T07:58:54.222+0000] {processor.py:756} INFO - Processing file /opt/airflow/dags/user_processing.py for tasks to queue
[2024-01-27T07:58:54.223+0000] {logging_mixin.py:120} INFO - [2024-01-27T07:58:54.223+0000] {dagbag.py:537} INFO - Filling up the DagBag from /opt/airflow/dags/user_processing.py
[2024-01-27T07:58:54.618+0000] {logging_mixin.py:120} INFO - [2024-01-27T07:58:54.615+0000] {dagbag.py:342} ERROR - Failed to import: /opt/airflow/dags/user_processing.py
Traceback (most recent call last):
  File "/home/airflow/.local/lib/python3.7/site-packages/airflow/models/dagbag.py", line 338, in parse
    loader.exec_module(new_module)
  File "<frozen importlib._bootstrap_external>", line 728, in exec_module
  File "<frozen importlib._bootstrap>", line 219, in _call_with_frames_removed
  File "/opt/airflow/dags/user_processing.py", line 62, in <module>
    python_callbale=_process_user
  File "/home/airflow/.local/lib/python3.7/site-packages/airflow/models/baseoperator.py", line 391, in apply_defaults
    raise AirflowException(f"missing keyword argument {missing_args.pop()!r}")
airflow.exceptions.AirflowException: missing keyword argument 'python_callable'
[2024-01-27T07:58:54.619+0000] {processor.py:768} WARNING - No viable dags retrieved from /opt/airflow/dags/user_processing.py
[2024-01-27T07:58:54.636+0000] {processor.py:176} INFO - Processing /opt/airflow/dags/user_processing.py took 0.420 seconds
[2024-01-27T07:59:24.901+0000] {processor.py:154} INFO - Started process (PID=2188) to work on /opt/airflow/dags/user_processing.py
[2024-01-27T07:59:24.905+0000] {processor.py:756} INFO - Processing file /opt/airflow/dags/user_processing.py for tasks to queue
[2024-01-27T07:59:24.907+0000] {logging_mixin.py:120} INFO - [2024-01-27T07:59:24.907+0000] {dagbag.py:537} INFO - Filling up the DagBag from /opt/airflow/dags/user_processing.py
[2024-01-27T07:59:25.393+0000] {logging_mixin.py:120} INFO - [2024-01-27T07:59:25.389+0000] {dagbag.py:342} ERROR - Failed to import: /opt/airflow/dags/user_processing.py
Traceback (most recent call last):
  File "/home/airflow/.local/lib/python3.7/site-packages/airflow/models/dagbag.py", line 338, in parse
    loader.exec_module(new_module)
  File "<frozen importlib._bootstrap_external>", line 728, in exec_module
  File "<frozen importlib._bootstrap>", line 219, in _call_with_frames_removed
  File "/opt/airflow/dags/user_processing.py", line 62, in <module>
    python_callbale=_process_user
  File "/home/airflow/.local/lib/python3.7/site-packages/airflow/models/baseoperator.py", line 391, in apply_defaults
    raise AirflowException(f"missing keyword argument {missing_args.pop()!r}")
airflow.exceptions.AirflowException: missing keyword argument 'python_callable'
[2024-01-27T07:59:25.399+0000] {processor.py:768} WARNING - No viable dags retrieved from /opt/airflow/dags/user_processing.py
[2024-01-27T07:59:25.431+0000] {processor.py:176} INFO - Processing /opt/airflow/dags/user_processing.py took 0.536 seconds
[2024-01-27T07:59:55.592+0000] {processor.py:154} INFO - Started process (PID=2251) to work on /opt/airflow/dags/user_processing.py
[2024-01-27T07:59:55.597+0000] {processor.py:756} INFO - Processing file /opt/airflow/dags/user_processing.py for tasks to queue
[2024-01-27T07:59:55.599+0000] {logging_mixin.py:120} INFO - [2024-01-27T07:59:55.598+0000] {dagbag.py:537} INFO - Filling up the DagBag from /opt/airflow/dags/user_processing.py
[2024-01-27T07:59:55.944+0000] {logging_mixin.py:120} INFO - [2024-01-27T07:59:55.940+0000] {dagbag.py:342} ERROR - Failed to import: /opt/airflow/dags/user_processing.py
Traceback (most recent call last):
  File "/home/airflow/.local/lib/python3.7/site-packages/airflow/models/dagbag.py", line 338, in parse
    loader.exec_module(new_module)
  File "<frozen importlib._bootstrap_external>", line 728, in exec_module
  File "<frozen importlib._bootstrap>", line 219, in _call_with_frames_removed
  File "/opt/airflow/dags/user_processing.py", line 62, in <module>
    python_callbale=_process_user
  File "/home/airflow/.local/lib/python3.7/site-packages/airflow/models/baseoperator.py", line 391, in apply_defaults
    raise AirflowException(f"missing keyword argument {missing_args.pop()!r}")
airflow.exceptions.AirflowException: missing keyword argument 'python_callable'
[2024-01-27T07:59:55.946+0000] {processor.py:768} WARNING - No viable dags retrieved from /opt/airflow/dags/user_processing.py
[2024-01-27T07:59:55.963+0000] {processor.py:176} INFO - Processing /opt/airflow/dags/user_processing.py took 0.375 seconds
[2024-01-27T08:00:26.257+0000] {processor.py:154} INFO - Started process (PID=2317) to work on /opt/airflow/dags/user_processing.py
[2024-01-27T08:00:26.260+0000] {processor.py:756} INFO - Processing file /opt/airflow/dags/user_processing.py for tasks to queue
[2024-01-27T08:00:26.261+0000] {logging_mixin.py:120} INFO - [2024-01-27T08:00:26.261+0000] {dagbag.py:537} INFO - Filling up the DagBag from /opt/airflow/dags/user_processing.py
[2024-01-27T08:00:26.721+0000] {logging_mixin.py:120} INFO - [2024-01-27T08:00:26.718+0000] {dagbag.py:342} ERROR - Failed to import: /opt/airflow/dags/user_processing.py
Traceback (most recent call last):
  File "/home/airflow/.local/lib/python3.7/site-packages/airflow/models/dagbag.py", line 338, in parse
    loader.exec_module(new_module)
  File "<frozen importlib._bootstrap_external>", line 728, in exec_module
  File "<frozen importlib._bootstrap>", line 219, in _call_with_frames_removed
  File "/opt/airflow/dags/user_processing.py", line 62, in <module>
    python_callbale=_process_user
  File "/home/airflow/.local/lib/python3.7/site-packages/airflow/models/baseoperator.py", line 391, in apply_defaults
    raise AirflowException(f"missing keyword argument {missing_args.pop()!r}")
airflow.exceptions.AirflowException: missing keyword argument 'python_callable'
[2024-01-27T08:00:26.723+0000] {processor.py:768} WARNING - No viable dags retrieved from /opt/airflow/dags/user_processing.py
[2024-01-27T08:00:26.742+0000] {processor.py:176} INFO - Processing /opt/airflow/dags/user_processing.py took 0.490 seconds
[2024-01-27T08:00:56.988+0000] {processor.py:154} INFO - Started process (PID=2382) to work on /opt/airflow/dags/user_processing.py
[2024-01-27T08:00:56.990+0000] {processor.py:756} INFO - Processing file /opt/airflow/dags/user_processing.py for tasks to queue
[2024-01-27T08:00:56.992+0000] {logging_mixin.py:120} INFO - [2024-01-27T08:00:56.992+0000] {dagbag.py:537} INFO - Filling up the DagBag from /opt/airflow/dags/user_processing.py
[2024-01-27T08:00:57.407+0000] {logging_mixin.py:120} INFO - [2024-01-27T08:00:57.403+0000] {dagbag.py:342} ERROR - Failed to import: /opt/airflow/dags/user_processing.py
Traceback (most recent call last):
  File "/home/airflow/.local/lib/python3.7/site-packages/airflow/models/dagbag.py", line 338, in parse
    loader.exec_module(new_module)
  File "<frozen importlib._bootstrap_external>", line 728, in exec_module
  File "<frozen importlib._bootstrap>", line 219, in _call_with_frames_removed
  File "/opt/airflow/dags/user_processing.py", line 62, in <module>
    python_callbale=_process_user
  File "/home/airflow/.local/lib/python3.7/site-packages/airflow/models/baseoperator.py", line 391, in apply_defaults
    raise AirflowException(f"missing keyword argument {missing_args.pop()!r}")
airflow.exceptions.AirflowException: missing keyword argument 'python_callable'
[2024-01-27T08:00:57.410+0000] {processor.py:768} WARNING - No viable dags retrieved from /opt/airflow/dags/user_processing.py
[2024-01-27T08:00:57.425+0000] {processor.py:176} INFO - Processing /opt/airflow/dags/user_processing.py took 0.440 seconds
[2024-01-27T08:01:28.271+0000] {processor.py:154} INFO - Started process (PID=2445) to work on /opt/airflow/dags/user_processing.py
[2024-01-27T08:01:28.274+0000] {processor.py:756} INFO - Processing file /opt/airflow/dags/user_processing.py for tasks to queue
[2024-01-27T08:01:28.276+0000] {logging_mixin.py:120} INFO - [2024-01-27T08:01:28.276+0000] {dagbag.py:537} INFO - Filling up the DagBag from /opt/airflow/dags/user_processing.py
[2024-01-27T08:01:28.734+0000] {logging_mixin.py:120} INFO - [2024-01-27T08:01:28.730+0000] {dagbag.py:342} ERROR - Failed to import: /opt/airflow/dags/user_processing.py
Traceback (most recent call last):
  File "/home/airflow/.local/lib/python3.7/site-packages/airflow/models/dagbag.py", line 338, in parse
    loader.exec_module(new_module)
  File "<frozen importlib._bootstrap_external>", line 728, in exec_module
  File "<frozen importlib._bootstrap>", line 219, in _call_with_frames_removed
  File "/opt/airflow/dags/user_processing.py", line 62, in <module>
    python_callbale=_process_user
  File "/home/airflow/.local/lib/python3.7/site-packages/airflow/models/baseoperator.py", line 391, in apply_defaults
    raise AirflowException(f"missing keyword argument {missing_args.pop()!r}")
airflow.exceptions.AirflowException: missing keyword argument 'python_callable'
[2024-01-27T08:01:28.736+0000] {processor.py:768} WARNING - No viable dags retrieved from /opt/airflow/dags/user_processing.py
[2024-01-27T08:01:28.756+0000] {processor.py:176} INFO - Processing /opt/airflow/dags/user_processing.py took 0.488 seconds
[2024-01-27T08:01:59.698+0000] {processor.py:154} INFO - Started process (PID=2501) to work on /opt/airflow/dags/user_processing.py
[2024-01-27T08:01:59.702+0000] {processor.py:756} INFO - Processing file /opt/airflow/dags/user_processing.py for tasks to queue
[2024-01-27T08:01:59.704+0000] {logging_mixin.py:120} INFO - [2024-01-27T08:01:59.704+0000] {dagbag.py:537} INFO - Filling up the DagBag from /opt/airflow/dags/user_processing.py
[2024-01-27T08:02:00.186+0000] {logging_mixin.py:120} INFO - [2024-01-27T08:02:00.180+0000] {dagbag.py:342} ERROR - Failed to import: /opt/airflow/dags/user_processing.py
Traceback (most recent call last):
  File "/home/airflow/.local/lib/python3.7/site-packages/airflow/models/dagbag.py", line 338, in parse
    loader.exec_module(new_module)
  File "<frozen importlib._bootstrap_external>", line 728, in exec_module
  File "<frozen importlib._bootstrap>", line 219, in _call_with_frames_removed
  File "/opt/airflow/dags/user_processing.py", line 62, in <module>
    python_callbale=_process_user
  File "/home/airflow/.local/lib/python3.7/site-packages/airflow/models/baseoperator.py", line 391, in apply_defaults
    raise AirflowException(f"missing keyword argument {missing_args.pop()!r}")
airflow.exceptions.AirflowException: missing keyword argument 'python_callable'
[2024-01-27T08:02:00.189+0000] {processor.py:768} WARNING - No viable dags retrieved from /opt/airflow/dags/user_processing.py
[2024-01-27T08:02:00.213+0000] {processor.py:176} INFO - Processing /opt/airflow/dags/user_processing.py took 0.521 seconds
[2024-01-27T08:02:30.974+0000] {processor.py:154} INFO - Started process (PID=2566) to work on /opt/airflow/dags/user_processing.py
[2024-01-27T08:02:30.978+0000] {processor.py:756} INFO - Processing file /opt/airflow/dags/user_processing.py for tasks to queue
[2024-01-27T08:02:30.980+0000] {logging_mixin.py:120} INFO - [2024-01-27T08:02:30.980+0000] {dagbag.py:537} INFO - Filling up the DagBag from /opt/airflow/dags/user_processing.py
[2024-01-27T08:02:31.412+0000] {logging_mixin.py:120} INFO - [2024-01-27T08:02:31.408+0000] {dagbag.py:342} ERROR - Failed to import: /opt/airflow/dags/user_processing.py
Traceback (most recent call last):
  File "/home/airflow/.local/lib/python3.7/site-packages/airflow/models/dagbag.py", line 338, in parse
    loader.exec_module(new_module)
  File "<frozen importlib._bootstrap_external>", line 728, in exec_module
  File "<frozen importlib._bootstrap>", line 219, in _call_with_frames_removed
  File "/opt/airflow/dags/user_processing.py", line 62, in <module>
    python_callbale=_process_user
  File "/home/airflow/.local/lib/python3.7/site-packages/airflow/models/baseoperator.py", line 391, in apply_defaults
    raise AirflowException(f"missing keyword argument {missing_args.pop()!r}")
airflow.exceptions.AirflowException: missing keyword argument 'python_callable'
[2024-01-27T08:02:31.414+0000] {processor.py:768} WARNING - No viable dags retrieved from /opt/airflow/dags/user_processing.py
[2024-01-27T08:02:31.430+0000] {processor.py:176} INFO - Processing /opt/airflow/dags/user_processing.py took 0.460 seconds
[2024-01-27T08:03:02.336+0000] {processor.py:154} INFO - Started process (PID=2635) to work on /opt/airflow/dags/user_processing.py
[2024-01-27T08:03:02.340+0000] {processor.py:756} INFO - Processing file /opt/airflow/dags/user_processing.py for tasks to queue
[2024-01-27T08:03:02.342+0000] {logging_mixin.py:120} INFO - [2024-01-27T08:03:02.342+0000] {dagbag.py:537} INFO - Filling up the DagBag from /opt/airflow/dags/user_processing.py
[2024-01-27T08:03:02.772+0000] {logging_mixin.py:120} INFO - [2024-01-27T08:03:02.768+0000] {dagbag.py:342} ERROR - Failed to import: /opt/airflow/dags/user_processing.py
Traceback (most recent call last):
  File "/home/airflow/.local/lib/python3.7/site-packages/airflow/models/dagbag.py", line 338, in parse
    loader.exec_module(new_module)
  File "<frozen importlib._bootstrap_external>", line 728, in exec_module
  File "<frozen importlib._bootstrap>", line 219, in _call_with_frames_removed
  File "/opt/airflow/dags/user_processing.py", line 62, in <module>
    python_callbale=_process_user
  File "/home/airflow/.local/lib/python3.7/site-packages/airflow/models/baseoperator.py", line 391, in apply_defaults
    raise AirflowException(f"missing keyword argument {missing_args.pop()!r}")
airflow.exceptions.AirflowException: missing keyword argument 'python_callable'
[2024-01-27T08:03:02.774+0000] {processor.py:768} WARNING - No viable dags retrieved from /opt/airflow/dags/user_processing.py
[2024-01-27T08:03:02.790+0000] {processor.py:176} INFO - Processing /opt/airflow/dags/user_processing.py took 0.460 seconds
[2024-01-27T08:03:33.083+0000] {processor.py:154} INFO - Started process (PID=2701) to work on /opt/airflow/dags/user_processing.py
[2024-01-27T08:03:33.086+0000] {processor.py:756} INFO - Processing file /opt/airflow/dags/user_processing.py for tasks to queue
[2024-01-27T08:03:33.089+0000] {logging_mixin.py:120} INFO - [2024-01-27T08:03:33.089+0000] {dagbag.py:537} INFO - Filling up the DagBag from /opt/airflow/dags/user_processing.py
[2024-01-27T08:03:33.494+0000] {logging_mixin.py:120} INFO - [2024-01-27T08:03:33.491+0000] {dagbag.py:342} ERROR - Failed to import: /opt/airflow/dags/user_processing.py
Traceback (most recent call last):
  File "/home/airflow/.local/lib/python3.7/site-packages/airflow/models/dagbag.py", line 338, in parse
    loader.exec_module(new_module)
  File "<frozen importlib._bootstrap_external>", line 728, in exec_module
  File "<frozen importlib._bootstrap>", line 219, in _call_with_frames_removed
  File "/opt/airflow/dags/user_processing.py", line 62, in <module>
    python_callbale=_process_user
  File "/home/airflow/.local/lib/python3.7/site-packages/airflow/models/baseoperator.py", line 391, in apply_defaults
    raise AirflowException(f"missing keyword argument {missing_args.pop()!r}")
airflow.exceptions.AirflowException: missing keyword argument 'python_callable'
[2024-01-27T08:03:33.498+0000] {processor.py:768} WARNING - No viable dags retrieved from /opt/airflow/dags/user_processing.py
[2024-01-27T08:03:33.513+0000] {processor.py:176} INFO - Processing /opt/airflow/dags/user_processing.py took 0.436 seconds
[2024-01-27T08:04:04.281+0000] {processor.py:154} INFO - Started process (PID=2767) to work on /opt/airflow/dags/user_processing.py
[2024-01-27T08:04:04.284+0000] {processor.py:756} INFO - Processing file /opt/airflow/dags/user_processing.py for tasks to queue
[2024-01-27T08:04:04.287+0000] {logging_mixin.py:120} INFO - [2024-01-27T08:04:04.287+0000] {dagbag.py:537} INFO - Filling up the DagBag from /opt/airflow/dags/user_processing.py
[2024-01-27T08:04:04.717+0000] {logging_mixin.py:120} INFO - [2024-01-27T08:04:04.713+0000] {dagbag.py:342} ERROR - Failed to import: /opt/airflow/dags/user_processing.py
Traceback (most recent call last):
  File "/home/airflow/.local/lib/python3.7/site-packages/airflow/models/dagbag.py", line 338, in parse
    loader.exec_module(new_module)
  File "<frozen importlib._bootstrap_external>", line 728, in exec_module
  File "<frozen importlib._bootstrap>", line 219, in _call_with_frames_removed
  File "/opt/airflow/dags/user_processing.py", line 62, in <module>
    python_callbale=_process_user
  File "/home/airflow/.local/lib/python3.7/site-packages/airflow/models/baseoperator.py", line 391, in apply_defaults
    raise AirflowException(f"missing keyword argument {missing_args.pop()!r}")
airflow.exceptions.AirflowException: missing keyword argument 'python_callable'
[2024-01-27T08:04:04.719+0000] {processor.py:768} WARNING - No viable dags retrieved from /opt/airflow/dags/user_processing.py
[2024-01-27T08:04:04.737+0000] {processor.py:176} INFO - Processing /opt/airflow/dags/user_processing.py took 0.460 seconds
