[2024-01-27T15:45:05.844+0000] {taskinstance.py:1165} INFO - Dependencies all met for <TaskInstance: user_processing_dag.process_user manual__2024-01-27T15:44:59.931765+00:00 [queued]>
[2024-01-27T15:45:05.853+0000] {taskinstance.py:1165} INFO - Dependencies all met for <TaskInstance: user_processing_dag.process_user manual__2024-01-27T15:44:59.931765+00:00 [queued]>
[2024-01-27T15:45:05.856+0000] {taskinstance.py:1362} INFO - 
--------------------------------------------------------------------------------
[2024-01-27T15:45:05.858+0000] {taskinstance.py:1363} INFO - Starting attempt 1 of 1
[2024-01-27T15:45:05.860+0000] {taskinstance.py:1364} INFO - 
--------------------------------------------------------------------------------
[2024-01-27T15:45:05.872+0000] {taskinstance.py:1383} INFO - Executing <Task(PythonOperator): process_user> on 2024-01-27 15:44:59.931765+00:00
[2024-01-27T15:45:05.885+0000] {standard_task_runner.py:55} INFO - Started process 5458 to run task
[2024-01-27T15:45:05.892+0000] {standard_task_runner.py:82} INFO - Running: ['***', 'tasks', 'run', 'user_processing_dag', 'process_user', 'manual__2024-01-27T15:44:59.931765+00:00', '--job-id', '19', '--raw', '--subdir', 'DAGS_FOLDER/user_processing_dag.py', '--cfg-path', '/tmp/tmp4m6cvyic']
[2024-01-27T15:45:05.897+0000] {standard_task_runner.py:83} INFO - Job 19: Subtask process_user
[2024-01-27T15:45:05.954+0000] {task_command.py:376} INFO - Running <TaskInstance: user_processing_dag.process_user manual__2024-01-27T15:44:59.931765+00:00 [running]> on host 0c5b25b371b7
[2024-01-27T15:45:06.005+0000] {taskinstance.py:1592} INFO - Exporting the following env vars:
AIRFLOW_CTX_DAG_OWNER=***
AIRFLOW_CTX_DAG_ID=user_processing_dag
AIRFLOW_CTX_TASK_ID=process_user
AIRFLOW_CTX_EXECUTION_DATE=2024-01-27T15:44:59.931765+00:00
AIRFLOW_CTX_TRY_NUMBER=1
AIRFLOW_CTX_DAG_RUN_ID=manual__2024-01-27T15:44:59.931765+00:00
[2024-01-27T15:45:06.019+0000] {taskinstance.py:1851} ERROR - Task failed with exception
Traceback (most recent call last):
  File "/home/airflow/.local/lib/python3.7/site-packages/airflow/operators/python.py", line 175, in execute
    return_value = self.execute_callable()
  File "/home/airflow/.local/lib/python3.7/site-packages/airflow/operators/python.py", line 193, in execute_callable
    return self.python_callable(*self.op_args, **self.op_kwargs)
  File "/opt/airflow/dags/user_processing_dag.py", line 14, in _process_user
    user = user ['resuts'][0]
KeyError: 'resuts'
[2024-01-27T15:45:06.037+0000] {taskinstance.py:1406} INFO - Marking task as FAILED. dag_id=user_processing_dag, task_id=process_user, execution_date=20240127T154459, start_date=20240127T154505, end_date=20240127T154506
[2024-01-27T15:45:06.047+0000] {standard_task_runner.py:105} ERROR - Failed to execute job 19 for task process_user ('resuts'; 5458)
[2024-01-27T15:45:06.067+0000] {local_task_job.py:164} INFO - Task exited with return code 1
[2024-01-27T15:45:06.082+0000] {local_task_job.py:273} INFO - 0 downstream tasks scheduled from follow-on schedule check
