[2024-01-27T15:59:22.561+0000] {taskinstance.py:1165} INFO - Dependencies all met for <TaskInstance: user_processing_dag.process_user manual__2024-01-27T15:59:16.129820+00:00 [queued]>
[2024-01-27T15:59:22.570+0000] {taskinstance.py:1165} INFO - Dependencies all met for <TaskInstance: user_processing_dag.process_user manual__2024-01-27T15:59:16.129820+00:00 [queued]>
[2024-01-27T15:59:22.571+0000] {taskinstance.py:1362} INFO - 
--------------------------------------------------------------------------------
[2024-01-27T15:59:22.572+0000] {taskinstance.py:1363} INFO - Starting attempt 1 of 1
[2024-01-27T15:59:22.573+0000] {taskinstance.py:1364} INFO - 
--------------------------------------------------------------------------------
[2024-01-27T15:59:22.582+0000] {taskinstance.py:1383} INFO - Executing <Task(PythonOperator): process_user> on 2024-01-27 15:59:16.129820+00:00
[2024-01-27T15:59:22.587+0000] {standard_task_runner.py:55} INFO - Started process 6166 to run task
[2024-01-27T15:59:22.590+0000] {standard_task_runner.py:82} INFO - Running: ['***', 'tasks', 'run', 'user_processing_dag', 'process_user', 'manual__2024-01-27T15:59:16.129820+00:00', '--job-id', '23', '--raw', '--subdir', 'DAGS_FOLDER/user_processing_dag.py', '--cfg-path', '/tmp/tmpv75_drad']
[2024-01-27T15:59:22.592+0000] {standard_task_runner.py:83} INFO - Job 23: Subtask process_user
[2024-01-27T15:59:22.640+0000] {task_command.py:376} INFO - Running <TaskInstance: user_processing_dag.process_user manual__2024-01-27T15:59:16.129820+00:00 [running]> on host 0c5b25b371b7
[2024-01-27T15:59:22.683+0000] {taskinstance.py:1592} INFO - Exporting the following env vars:
AIRFLOW_CTX_DAG_OWNER=***
AIRFLOW_CTX_DAG_ID=user_processing_dag
AIRFLOW_CTX_TASK_ID=process_user
AIRFLOW_CTX_EXECUTION_DATE=2024-01-27T15:59:16.129820+00:00
AIRFLOW_CTX_TRY_NUMBER=1
AIRFLOW_CTX_DAG_RUN_ID=manual__2024-01-27T15:59:16.129820+00:00
[2024-01-27T15:59:22.692+0000] {taskinstance.py:1851} ERROR - Task failed with exception
Traceback (most recent call last):
  File "/home/airflow/.local/lib/python3.7/site-packages/airflow/operators/python.py", line 175, in execute
    return_value = self.execute_callable()
  File "/home/airflow/.local/lib/python3.7/site-packages/airflow/operators/python.py", line 193, in execute_callable
    return self.python_callable(*self.op_args, **self.op_kwargs)
  File "/opt/airflow/dags/user_processing_dag.py", line 14, in _process_user
    user = user ['resuts'][0]
KeyError: 'resuts'
[2024-01-27T15:59:22.703+0000] {taskinstance.py:1406} INFO - Marking task as FAILED. dag_id=user_processing_dag, task_id=process_user, execution_date=20240127T155916, start_date=20240127T155922, end_date=20240127T155922
[2024-01-27T15:59:22.711+0000] {standard_task_runner.py:105} ERROR - Failed to execute job 23 for task process_user ('resuts'; 6166)
[2024-01-27T15:59:22.723+0000] {local_task_job.py:164} INFO - Task exited with return code 1
[2024-01-27T15:59:22.744+0000] {local_task_job.py:273} INFO - 0 downstream tasks scheduled from follow-on schedule check
