[2024-01-27T17:58:48.871+0000] {taskinstance.py:1165} INFO - Dependencies all met for <TaskInstance: user_processing_dag.store_user manual__2024-01-27T17:58:41.123558+00:00 [queued]>
[2024-01-27T17:58:48.879+0000] {taskinstance.py:1165} INFO - Dependencies all met for <TaskInstance: user_processing_dag.store_user manual__2024-01-27T17:58:41.123558+00:00 [queued]>
[2024-01-27T17:58:48.880+0000] {taskinstance.py:1362} INFO - 
--------------------------------------------------------------------------------
[2024-01-27T17:58:48.881+0000] {taskinstance.py:1363} INFO - Starting attempt 1 of 1
[2024-01-27T17:58:48.882+0000] {taskinstance.py:1364} INFO - 
--------------------------------------------------------------------------------
[2024-01-27T17:58:48.890+0000] {taskinstance.py:1383} INFO - Executing <Task(PythonOperator): store_user> on 2024-01-27 17:58:41.123558+00:00
[2024-01-27T17:58:48.894+0000] {standard_task_runner.py:55} INFO - Started process 7901 to run task
[2024-01-27T17:58:48.897+0000] {standard_task_runner.py:82} INFO - Running: ['***', 'tasks', 'run', 'user_processing_dag', 'store_user', 'manual__2024-01-27T17:58:41.123558+00:00', '--job-id', '40', '--raw', '--subdir', 'DAGS_FOLDER/user_processing_dag.py', '--cfg-path', '/tmp/tmp7bnw6y1q']
[2024-01-27T17:58:48.900+0000] {standard_task_runner.py:83} INFO - Job 40: Subtask store_user
[2024-01-27T17:58:48.955+0000] {task_command.py:376} INFO - Running <TaskInstance: user_processing_dag.store_user manual__2024-01-27T17:58:41.123558+00:00 [running]> on host 0c5b25b371b7
[2024-01-27T17:58:49.003+0000] {taskinstance.py:1592} INFO - Exporting the following env vars:
AIRFLOW_CTX_DAG_OWNER=***
AIRFLOW_CTX_DAG_ID=user_processing_dag
AIRFLOW_CTX_TASK_ID=store_user
AIRFLOW_CTX_EXECUTION_DATE=2024-01-27T17:58:41.123558+00:00
AIRFLOW_CTX_TRY_NUMBER=1
AIRFLOW_CTX_DAG_RUN_ID=manual__2024-01-27T17:58:41.123558+00:00
[2024-01-27T17:58:49.005+0000] {taskinstance.py:1851} ERROR - Task failed with exception
Traceback (most recent call last):
  File "/home/airflow/.local/lib/python3.7/site-packages/airflow/operators/python.py", line 175, in execute
    return_value = self.execute_callable()
  File "/home/airflow/.local/lib/python3.7/site-packages/airflow/operators/python.py", line 193, in execute_callable
    return self.python_callable(*self.op_args, **self.op_kwargs)
  File "/opt/airflow/dags/user_processing_dag.py", line 25, in _store_user
    hook = PostgresHook(postgres_conn_id='postgres')
NameError: name 'PostgresHook' is not defined
[2024-01-27T17:58:49.015+0000] {taskinstance.py:1406} INFO - Marking task as FAILED. dag_id=user_processing_dag, task_id=store_user, execution_date=20240127T175841, start_date=20240127T175848, end_date=20240127T175849
[2024-01-27T17:58:49.024+0000] {standard_task_runner.py:105} ERROR - Failed to execute job 40 for task store_user (name 'PostgresHook' is not defined; 7901)
[2024-01-27T17:58:49.031+0000] {local_task_job.py:164} INFO - Task exited with return code 1
[2024-01-27T17:58:49.047+0000] {local_task_job.py:273} INFO - 0 downstream tasks scheduled from follow-on schedule check
